Workbook

Sheet Financials
A1: Financial
A2: Rev 0
F3: Value
A4: Customer | B4: Request / Day | C4: Compute Time (sec) / Request | D4: # GPUs Allocated / Request | E4: GPU Power (W) / Request | F4: $ / GPU Hr <1 sec | G4: $ / GPU Hr <20 sec | H4: Active GPU Hrs / Month | I4: Active Servers Hrs/Month | J4: Revenue / Month | K4: Active Power Cost w/o Loss
A5: A | B5: =Load!B19 -> 60000000 | C5: 0.5 | D5: 1 | E5: 600 | F5: =Load!D19 -> 6 | G5: =Load!E19 -> 3 | H5: =(C5*B5*D5*30)/(60*60) -> 250000 | I5: =H5/B$13 -> 31250 | J5: =(IF(C5<1,F5,G5))*H5 -> 1500000 | K5: =((H5*E5/1000)+I5*B$15)*B$22 -> 55000
A6: B | B6: =Load!B20 -> 30000000 | C6: 10 | D6: 4 | E6: 700 | F6: =Load!D20 -> 8 | G6: =Load!E20 -> 6 | H6: =(C6*B6*D6*30)/(60*60) -> 10000000 | I6: =H6/B$13 -> 1250000 | J6: =(IF(C6<1,F6,G6))*H6 -> 60000000 | K6: =((H6*E6/1000)+I6*B$15)*B$22 -> 2400000
A7: C | B7: =Load!B21 -> 10000000 | C7: 15 | D7: 16 | E7: 800 | F7: =Load!D21 -> 15 | G7: =Load!E21 -> 13 | H7: =(C7*B7*D7*30)/(60*60) -> 20000000 | I7: =H7/B$13 -> 2500000 | J7: =(IF(C7<1,F7,G7))*H7 -> 260000000 | K7: =((H7*E7/1000)+I7*B$15)*B$22 -> 5200000
A8: Total | B8: =SUM(B5:B7) -> 100000000 | H8: =SUM(H5:H7) -> 30250000 | I8: =SUM(I5:I7) -> 3781250 | J8: =SUM(J5:J7) -> 321500000 | K8: =SUM(K5:K7) -> 7655000
A10: Operating Parameters | E10: Key Values for Checks or Limits | H10: Orange Cells
A11: Number of Racks | B11: 100 | E11: Max Rack Hours | F11: =30*24*B11 -> 72000 | H11: Values to link or enter based on other modeling
A12: Servers / Rack | B12: 4 | E12: Max Server Hours | F12: =F11*B12 -> 288000
A13: GPUs / Server | B13: 8 | E13: Max GPU Hours | F13: =F12*B13 -> 2304000
A14: Server Type | B14: Water | C14: "Water" or "Air" | E14: Peak GPUs Requested | F14: =(D5*B5+B6*D6+B7*D7)/(24*60*60) -> 3935.1852 | G14: If everything happens at once
A15: Total Active Power / Server w/o GPU | B15: 4 | C15: kW | E15: Max Power Cost | F15: =(B22*B16*F11)/(1-B19) -> 668463.16 | G15: 100% Utilized
A16: Max Active Power / Rack | B16: =C31+(IF(B14="Water",C32,0))+((MAX(E5:E7)/1000)*B13+B15)*B12 -> 44.1 | C16: kW
A17: Idle Power / Server | B17: 2 | E17: Checks
A18: Max Power / Rack | B18: 50 | C18: kW | E18: Peak GPU > Max GPU | F18: =IF(F14> (B11*B12*B13), "Issue", "Ok") -> Issue | G18: Issue => Risk of peak load causing slower times
A19: Power loss to Rack | B19: 0.05 | E19: Oversubscribed Servers | F19: =IF(I8>F12, "Broken", "Ok") -> Broken | G19: Broken => Does not meet requirement constraint
A20: Maintenance/Rack | B20: 500 | C20: /month | E20: Oversubscribed Power | F20: =IF(B16 > B18, "Broken", "Ok") -> Ok | G20: Ok => Within requirement / constraint
A21: Overhead/Rack | B21: 100 | C21: /month
A22: kWh | B22: 0.2 | F22: Monthly
E23: Revenue | F23: =J8 -> 321500000
A24: Server Amoritzation with Rack Overhead | E24: Server Amortization | F24: =B11*B12*B28 -> 1672127.9
A25: Server Cost + Rack Overhead | B25: =D40+B33 -> 196250 | E25: Active Power Cost | F25: =SUM(K5:K7)/(1-B19) -> 8057894.7
A26: Amoritization Period | B26: 50 | C26: Months | E26: Idle Power Cost | F26: =((F12-I8)*B17*B22)/(1-B19) -> -1470842.1
A27: Amoritization Interest | B27: 0.03 | E27: Other Cost | F27: =(B20+B21)*B11 -> 60000
A28: Monthly Amortization | B28: =-1*PMT(B27/12,B26,B25,0) -> 4180.3197 | C28: /month | E28: Operating Cost | F28: =SUM(F24:F27) -> 8319180.5
E29: Net Profit | F29: =F23-SUM(F24:F27) -> 3.1318082e+08
A30: Rack Cost | B30: Cost | C30: Power (kW)
A31: ToR Enet Switch | B31: 4000 | C31: 1 | D31: kW
A32: CDU | B32: 5000 | C32: 1.5 | D32: kW
A33: Rack Cost Overhead to add per Server | B33: =(IF(B14="Water",(B31+B32),B31))/B12 -> 2250
A35: Server Cost | B35: Qty | C35: Unit Cost | D35: Unit Total
A36: Mainboard, Memory, Smart NIC, etc | B36: 1 | C36: 25000 | D36: =B36*C36 -> 25000
A37: CPU Cost | B37: 2 | C37: 4500 | D37: =B37*C37 -> 9000 | F37: Case, PSU, Thermal, etc
A38: GPU Cost | B38: 8 | C38: 20000 | D38: =B38*C38 -> 160000 | F38: Air Cooled | G38: Water Cooled
A39: Case, PSU, Thermal, etc | B39: 1 | C39: =IF(B14="Water",G39,F39) -> 30000 | D39: =B39*C39 -> 30000 | E39: <------------------------ | F39: 25000 | G39: 30000
C40: TOTAL | D40: =SUM(D36:D38) -> 194000

Sheet CPU
A1: CPU Table | B1: 45922 | D1: Estimates | E1: Yellow cells are judged estimates if data is not easily available
B3: INTEL
A4: Processor | B4: Sims | C4: Leavitt | D4: 6774P | E4: 6978P | F4: Notes / Description
A5: Market Focus | B5: Server | C5: Server | D5: Server | E5: Server | F5: Target Market
A6: Family | B6: Xeon 6 | C6: Xeon 6 | D6: Xeon 6 | E6: Xeon 6 | F6: Family Name / Architecture (each processor can be tuned within family)
A7: ASP Volume | B7: 1200 | C7: 1600 | D7: 2400 | E7: 4500 | F7: Customer low volume price
A8: Cores | B8: 32 | C8: 40 | D8: 64 | E8: 120 | F8: Physical cores
A9: Threads | B9: 64 | C9: 80 | D9: 128 | E9: 240 | F9: 2 Threads/core
A10: Max Frequency | B10: 2.5 | C10: 2.5 | D10: 2.5 | E10: 2.1 | F10: Max clock with all running
A11: Turbo Frequency | B11: 3.3 | C11: 3.5 | D11: 3.9 | E11: 3.9 | F11: Boost clock in special conditions
A12: TDP | B12: 250 | C12: 400 | D12: 350 | E12: 500 | F12: Thermal power
A13: Vcore @ Load | B13: 1.5 | C13: 1.5 | D13: 1.5 | E13: 1.5 | F13: Vcc_core Max is 1.72V … normally just used at Turbo
A14: Process | B14: Intel 3 | C14: Intel 3 | D14: Intel 3 | E14: Intel 3 | F14: Fab or Process family (each processor can be tuned within family)
A15: Tcase | B15: 85 | C15: 85 | D15: 81 | E15: 80 | F15: Max Temp of case / integrated heat spreader;
A16: Max Tjunction = Tj_max | B16: 100 | C16: 100 | D16: 100 | E16: 100 | F16: Based on Ultra Core i9 spec; Intel statement is this is between 100-110C
A18: Translation Calculations
A19: Tjunction for TDP | B19: 70C | C19: 70C | D19: 70C | E19: 70C | F19: This is between 50-70C
A20: High_Load for TDP | B20: 0.7 | C20: 0.7 | D20: 0.7 | E20: 0.7 | F20: Load is normally 70-80th percential based on measured & at Max Frequency
A21: Active Power split @ Load | B21: 0.5 | C21: 0.5 | D21: 0.5 | E21: 0.5 | F21: Modern process at 70C typically are around 50/50
A22: Active Power @ Load | B22: =B21*B12 -> 125 | C22: =C21*C12 -> 200 | D22: =D21*D12 -> 175 | E22: =E21*E12 -> 250
A23: Leakage Power @ Load | B23: =(1-B21)*B12 -> 125 | C23: =(1-C21)*C12 -> 200 | D23: =(1-D21)*D12 -> 175 | E23: =(1-E21)*E12 -> 250
A24: Leakage Scaling @ Tj_max | B24: 1 | C24: 1 | D24: 1 | E24: 1 | F24: Modern process have a big Temperature component
A25: Leakage Power @ Tj_max | B25: =(1+B24)*B23 -> 250 | C25: =(1+C24)*C23 -> 400 | D25: =(1+D24)*D23 -> 350 | E25: =(1+E24)*E23 -> 500
A26: Switching Cap @ High_Load | B26: 22.22 | C26: =C22/(C10*C13^2) -> 35.555556 | D26: =D22/(D10*D13^2) -> 31.111111 | E26: =E22/(E10*E13^2) -> 52.910053 | F26: Active Power = C*V^2*F (first order)
A27: Peak_Load | B27: 0.95 | C27: 0.95 | D27: 0.95 | E27: 0.95
A28: Switching Cap @ Peak_Load | B28: =B26*(B27/B20) -> 30.155714 | C28: =C26*(C27/C20) -> 48.253968 | D28: =D26*(D27/D20) -> 42.222222 | E28: =E26*(E27/E20) -> 71.8065 | F28: Scales up from High_Load by more load being switched
A29: Active Power @ Peak_Load | B29: =B28*B10*B13^2 -> 169.62589 | C29: =C28*C10*C13^2 -> 271.42857 | D29: =D28*D10*D13^2 -> 237.5 | E29: =E28*E10*E13^2 -> 339.28571
A30: Power @ Peak_Load & Tj_max | B30: =B25+B29 -> 419.62589 | C30: =C25+C29 -> 671.42857 | D30: =D25+D29 -> 587.5 | E30: =E25+E29 -> 839.28571
A31: TDP to EDP Scaling Factor | B31: 0 | C31: 0 | D31: 0 | E31: 0 | F31: Scale from Pead_Load @ Tj_max … different industry "rules of thumb"; Depends on processor and use cases
A32: High_Load for EDP | B32: =B30*(1+B31) -> 419.62589 | C32: =C30*(1+C31) -> 671.42857 | D32: =D30*(1+D31) -> 587.5 | E32: =E30*(1+E31) -> 839.28571
A34: Model Configuration | B34: 6543P-B | C34: 6716P-B | D34: 6774P | E34: 6978P
A35: MaxCores | B35: 50 | C35: 3 | D35: =D8 -> 64 | E35: =E8 -> 120 | F35: Number of cores that can be used to process a compule load
A36: MaxFrequency | B36: =B10*1000 -> 2500 | C36: =C10*1000 -> 2500 | D36: =D10*1000 -> 2500 | E36: =E10*1000 -> 2100 | F36: Maximum clock rate of the cores in the processor in MHz
A37: ActiveSwitchCapacitance | B37: =B26 -> 22.22 | C37: =C26 -> 35.555556 | D37: =D26 -> 31.111111 | E37: =E26 -> 52.910053 | F37: The Active Switching Capacitance of a processor at the specified loading point (LoadPoint) that is used to determne the active power consuption in uF
A38: EDP | B38: =B32 -> 419.62589 | C38: =C32 -> 671.42857 | D38: =D32 -> 587.5 | E38: =E32 -> 839.28571 | F38: The electrical power drawn of the processor at the specified loading point (LoadPoint) in Watts
A39: TDP | B39: =B12 -> 250 | C39: =C12 -> 400 | D39: =D12 -> 350 | E39: =E12 -> 500 | F39: The thermal power emitted of the processor at the specified loading point (LoadPoint) in Watts
A40: LoadPoint | B40: =B20 -> 0.7 | C40: =C20 -> 0.7 | D40: =D20 -> 0.7 | E40: =E20 -> 0.7 | F40: The processor loading point based on a suite of applications that are used to define how much of the processor is typically switching as a %.
A41: Tjmax | B41: =B16 -> 100 | C41: =C16 -> 100 | D41: =D16 -> 100 | E41: =E16 -> 100 | F41: The maximum junction temperature (C) that the processor can reach and stay within it specified reliabily and functional parameters.
A43: DVFS Table | B43: 6543P-B | C43: 6716P-B | D43: 6774P | E43: 6978P
A44: F3 | B44: 2.5 | C44: =C10 -> 2.5 | D44: =D10 -> 2.5 | E44: =E10 -> 2.1 | F44: Fmax
...

Sheet GPU
A1: GPU Table | B1: 45922 | D1: Estimates
B3: NVIDIA
A4: Processor | B4: odoh | C4: brown | D4: Skattebo | E4: Notes / Description
A5: Market Focus | B5: Server | C5: Server | D5: Server | E5: Target Market
A6: Family | B6: Blackwell | C6: Blackwell | D6: Blackwell | E6: Family Name / Architecture (each processor can be tuned within family)
A7: ASP Volume | B7: 15000 | C7: 20000 | D7: 40000 | E7: Customer low volume price
A8: Cores | B8: 14000 | C8: 16896 | D8: 30000 | E8: Physical cores
A9: Max Frequency | B9: 1.8 | C9: 2 | D9: 2 | E9: Max clock with all running
A10: TOPS FP16 | B10: =C10*B8/C8 -> 2900.0947 | C10: 3500 | D10: =C10*D8/C8 -> 6214.4886 | E10: TOPs as a comparison
A11: TDP | B11: 600 | C11: 800 | D11: 1000 | E11: Thermal power
A12: Vcore @ Load | B12: 1 | C12: 1 | D12: 1 | E12: Vcc_core Max is 1.2V … normally just used for Overclocking
A13: Process | B13: TSMC 5nm (4NP) | C13: TSMC 5nm (4NP) | D13: TSMC 5nm (4NP) | E13: Fab or Process family (each processor can be tuned within family)
A14: Tcase | B14: 85 | C14: 85 | D14: 85 | E14: Max Temp of case / integrated heat spreader;
A15: Max Tjunction = Tj_max | B15: 95 | C15: 95 | D15: 95 | E15: Thermal data implies between 95C-110C
A17: Translation Calculations
A18: Tjunction for TDP | B18: 70C | C18: 70C | D18: 70C | E18: This is between 50-70C
A19: High_Load for TDP | B19: 0.75 | C19: 0.75 | D19: 0.75 | E19: Load is normally 70-80th percential based on measured & at Max Frequency
A20: Active Power split @ Load | B20: 0.5 | C20: 0.5 | D20: 0.5 | E20: Modern process at 70C typically are around 50/50
A21: Active Power @ Load | B21: =B20*B11 -> 300 | C21: =C20*C11 -> 400 | D21: =D20*D11 -> 500
A22: Leakage Power @ Load | B22: =(1-B20)*B11 -> 300 | C22: =(1-C20)*C11 -> 400 | D22: =(1-D20)*D11 -> 500
A23: Leakage Scaling @ Tj_max | B23: 1 | C23: 1 | D23: 1 | E23: Modern process have a big Temperature component
A24: Leakage Power @ Tj_max | B24: =(1+B23)*B22 -> 600 | C24: =(1+C23)*C22 -> 800 | D24: =(1+D23)*D22 -> 1000
A25: Switching Cap @ High_Load | B25: 166.67 | C25: 200 | D25: 250 | E25: Active Power = C*V^2*F (first order)
A26: Peak_Load | B26: 0.95 | C26: 0.95 | D26: 0.95
A27: Switching Cap @ Peak_Load | B27: =B25*(B26/B19) -> 211.11533 | C27: =C25*(C26/C19) -> 253.33333 | D27: =D25*(D26/D19) -> 316.66667 | E27: Scales up from High_Load by more load being switched
A28: Active Power @ Peak_Load | B28: =B27*B9*B12^2 -> 380.0076 | C28: =C27*C9*C12^2 -> 506.66667 | D28: =D27*D9*D12^2 -> 633.33333
A29: Power @ Peak_Load & Tj_max | B29: =B24+B28 -> 980.0076 | C29: =C24+C28 -> 1306.6667 | D29: =D24+D28 -> 1633.3333
A30: TDP to EDP Scaling Factor | B30: 0 | C30: 0 | D30: 0 | E30: Scale from Pead_Load @ Tj_max … different industry "rules of thumb"; Depends on processor and use cases
A31: High_Load for EDP | B31: =B29*(1+B30) -> 980.0076 | C31: =C29*(1+C30) -> 1306.6667 | D31: =D29*(1+D30) -> 1633.3333
A33: MatLab Configuration | B33: =B4 -> odoh | C33: =C4 -> brown | D33: =D4 -> Skattebo
A34: MaxCores | B34: 12000 | C34: 15000 | D34: 20000 | E34: Number of cores that can be used to process a compule load
A35: MaxFrequency | B35: =B9*1000 -> 1800 | C35: =C9*1000 -> 2000 | D35: =D9*1000 -> 2000 | E35: Maximum clock rate of the cores in the processor in MHz
A36: ActiveSwitchCapacitance | B36: =B25 -> 166.67 | C36: =C25 -> 200 | D36: =D25 -> 250 | E36: The Active Switching Capacitance of a processor at the specified loading point (LoadPoint) that is used to determne the active power consuption in uF
A37: EDP | B37: =B31 -> 980.0076 | C37: =C31 -> 1306.6667 | D37: =D31 -> 1633.3333 | E37: The electrical power drawn of the processor at the specified loading point (LoadPoint) in Watts
A38: TDP | B38: =B11 -> 600 | C38: =C11 -> 800 | D38: =D11 -> 1000 | E38: The thermal power emitted of the processor at the specified loading point (LoadPoint) in Watts
A39: LoadPoint | B39: =B19 -> 0.75 | C39: =C19 -> 0.75 | D39: =D19 -> 0.75 | E39: The processor loading point based on a suite of applications that are used to define how much of the processor is typically switching as a %.
A40: Tjmax | B40: =B15 -> 95 | C40: =C15 -> 95 | D40: =D15 -> 95 | E40: The maximum junction temperature (C) that the processor can reach and stay within it specified reliabily and functional parameters.
A42: DVFS Table | B42: =B4 -> odoh | C42: =C4 -> brown | D42: =D4 -> Skattebo
A43: F3 | B43: 1.8 | C43: 2 | D43: 2 | E43: Fmax
A44: V3 | B44: =B12 -> 1 | C44: =C12 -> 1 | D44: =D12 -> 1 | E44: Vmax
...

Sheet Load
A3: Updated Loading = Oct 22, 2025
B4: Compute A | C4: Compute AG | D4: Compute B | E4: Compute BG | F4: Compute C | G4: Compute CG
A5: Signal | B5: CPU | C5: GPU | D5: CPU | E5: GPU | F5: CPU | G5: GPU
A6: Init_Parallel | B6: 25 | C6: 10 | D6: 30 | E6: 12 | F6: 40 | G6: 12 | H6: Cores
A7: Init_Load | B7: 0.5 | C7: 0.1 | D7: 0.5 | E7: 0.1 | F7: 0.5 | G7: 0.1
A8: Init_Instr | B8: 200000 | C8: 20000 | D8: 500000 | E8: 40000 | F8: 1000000 | G8: 50000
A9: Main_Parallel | B9: 0 | C9: 10000 | D9: 0 | E9: 250000 | F9: 0 | G9: 250000 | H9: Cores
A10: Main_Load | B10: 0 | C10: 0.5 | D10: 0 | E10: 0.75 | F10: 0 | G10: 0.85
A11: Main_Instr | B11: 0 | C11: 20 | D11: 0 | E11: 2000 | F11: 0 | G11: 7500 | H11: TOPs
A12: Main_Instr_Scaling | B12: 1 | C12: 1.9 | D12: 1 | E12: 2.5 | F12: 1 | G12: 3.7 | H12: Instruction Precision Scaling Factor
A13: Result_Parallel | B13: 25 | C13: 10 | D13: 20 | E13: 5 | F13: 20 | G13: 5 | H13: Cores
A14: Result_Load | B14: 0.5 | C14: 0.1 | D14: 0.5 | E14: 0.1 | F14: 0.5 | G14: 0.1
A15: Result_Instr | B15: 100000 | C15: 10000 | D15: 100000 | E15: 10000 | F15: 100000 | G15: 10000
D17: Value
A18: Customer | B18: Request / Day | C18: AI Model Type | D18: $ / GPU Hr <1 sec | E18: $ / GPU Hr <20 sec | F18: Model Compute Instructions | H18: Tokens/ Response
A19: A | B19: 60000000 | C19: CNN | D19: 6 | E19: 3 | F19: 15 | G19: TOP
A20: B | B20: 30000000 | C20: LLM Small | D20: 8 | E20: 6 | F20: 1000 | G20: TOP | H20: 10 Token
A21: C | B21: 10000000 | C21: LLM Large | D21: 15 | E21: 13 | F21: 7500 | G21: TOP | H21: 40 Token
